<sdf version='1.10'>
  <world name='multicopter'>
    <physics name='4ms' type='ignored'>
      <max_step_size>0.0040000000000000001</max_step_size>
      <real_time_factor>1</real_time_factor>
      <real_time_update_rate>1000</real_time_update_rate>
    </physics>
    <plugin name='gz::sim::systems::Physics' filename='gz-sim-physics-system'/>
    <plugin name='gz::sim::systems::SceneBroadcaster' filename='gz-sim-scene-broadcaster-system'/>
    <plugin name='gz::sim::systems::UserCommands' filename='gz-sim-user-commands-system'/>
    <plugin name='gz::sim::systems::Sensors' filename='gz-sim-sensors-system'>
      <render_engine>ogre2</render_engine>
    </plugin>
    <gravity>0 0 -9.8000000000000007</gravity>
    <magnetic_field>5.5644999999999998e-06 2.2875799999999999e-05 -4.2388400000000002e-05</magnetic_field>
    <atmosphere type='adiabatic'/>
    <scene>
      <ambient>0.400000006 0.400000006 0.400000006 1</ambient>
      <background>0.699999988 0.699999988 0.699999988 1</background>
      <shadows>true</shadows>
    </scene>
    <model name='UAV_1'>
      <pose>-3.9226997795152377e-05 0.00023011687625889947 0.25847607258278033 -1.2804998462046923e-11 1.5129634773159107e-05 -1.2685004024676599e-07</pose>
      <link name='X3/base_link'>
        <pose>0 0 0 0 0 0</pose>
        <inertial>
          <pose>0 0 0 0 0 0</pose>
          <mass>1.5</mass>
          <inertia>
            <ixx>0.034756299999999997</ixx>
            <ixy>0</ixy>
            <ixz>0</ixz>
            <iyy>0.070000000000000007</iyy>
            <iyz>0</iyz>
            <izz>0.097699999999999995</izz>
          </inertia>
        </inertial>
        <collision name='X3/base_link_inertia_collision'>
          <pose>0 0 0 0 0 0</pose>
          <geometry>
            <box>
              <size>0.46999999999999997 0.46999999999999997 0.11</size>
            </box>
          </geometry>
          <surface>
            <friction>
              <ode/>
            </friction>
            <bounce/>
            <contact/>
          </surface>
        </collision>
        <visual name='X3/base_link_inertia_visual'>
          <pose>0 0 0 0 0 0</pose>
          <geometry>
            <mesh>
              <scale>1 1 1</scale>
              <uri>https://fuel.gazebosim.org/1.0/openrobotics/models/x3 uav/4/files/meshes/x3.dae</uri>
            </mesh>
          </geometry>
        </visual>
        <enable_wind>false</enable_wind>
      </link>
      <link name='X3/rotor_0'>
        <pose>0.13000000033607634 -0.21999990813411521 0.022999747848165386 -1.4279313210999648e-06 4.3693232738621749e-07 -2.8449414478027508</pose>
        <inertial>
          <pose>0 0 0 0 0 0</pose>
          <mass>0.0050000000000000001</mass>
          <inertia>
            <ixx>9.7499999999999998e-07</ixx>
            <ixy>0</ixy>
            <ixz>0</ixz>
            <iyy>4.1704099999999999e-05</iyy>
            <iyz>0</iyz>
            <izz>4.2604100000000001e-05</izz>
          </inertia>
        </inertial>
        <collision name='X3/rotor_0_collision'>
          <pose>0 0 0 0 0 0</pose>
          <geometry>
            <cylinder>
              <length>0.0050000000000000001</length>
              <radius>0.10000000000000001</radius>
            </cylinder>
          </geometry>
          <surface>
            <contact>
              <ode/>
            </contact>
            <friction>
              <ode/>
            </friction>
            <bounce/>
          </surface>
        </collision>
        <visual name='X3/rotor_0_visual'>
          <pose>0 0 0 0 0 0</pose>
          <geometry>
            <mesh>
              <scale>0.10000000000000001 0.10000000000000001 0.10000000000000001</scale>
              <uri>https://fuel.gazebosim.org/1.0/openrobotics/models/x3 uav/4/files/meshes/propeller_ccw.dae</uri>
            </mesh>
          </geometry>
          <material>
            <script>
              <name>Gazebo/Blue</name>
              <uri>file://media/materials/scripts/gazebo.material</uri>
            </script>
          </material>
        </visual>
        <gravity>true</gravity>
        <velocity_decay/>
        <enable_wind>false</enable_wind>
      </link>
      <joint name='X3/rotor_0_joint' type='revolute'>
        <child>X3/rotor_0</child>
        <parent>X3/base_link</parent>
        <axis>
          <xyz>2.6469779601696886e-23 2.1175823681357508e-22 1</xyz>
          <limit>
            <lower>-10000000000000000</lower>
            <upper>10000000000000000</upper>
            <effort>inf</effort>
            <velocity>inf</velocity>
            <stiffness>100000000</stiffness>
            <dissipation>1</dissipation>
          </limit>
          <dynamics>
            <spring_reference>0</spring_reference>
            <spring_stiffness>0</spring_stiffness>
            <damping>0</damping>
            <friction>0</friction>
          </dynamics>
        </axis>
        <pose>-7.6327832942979512e-17 2.2204460492503131e-16 6.9388939039072284e-18 -2.1175823681357508e-22 2.6469779601696886e-23 -2.8025969286496341e-45</pose>
      </joint>
      <link name='X3/rotor_1'>
        <pose>-0.12999999966491116 0.20000009186480541 0.023000374914267097 -1.4279192820905889e-06 4.3697166993676586e-07 -2.8449138955557944</pose>
        <inertial>
          <pose>0 0 0 0 0 0</pose>
          <mass>0.0050000000000000001</mass>
          <inertia>
            <ixx>9.7499999999999998e-07</ixx>
            <ixy>0</ixy>
            <ixz>0</ixz>
            <iyy>4.1704099999999999e-05</iyy>
            <iyz>0</iyz>
            <izz>4.2604100000000001e-05</izz>
          </inertia>
        </inertial>
        <collision name='X3/rotor_1_collision'>
          <pose>0 0 0 0 0 0</pose>
          <geometry>
            <cylinder>
              <length>0.0050000000000000001</length>
              <radius>0.10000000000000001</radius>
            </cylinder>
          </geometry>
          <surface>
            <contact>
              <ode/>
            </contact>
            <friction>
              <ode/>
            </friction>
            <bounce/>
          </surface>
        </collision>
        <visual name='X3/rotor_1_visual'>
          <pose>0 0 0 0 0 0</pose>
          <geometry>
            <mesh>
              <scale>0.10000000000000001 0.10000000000000001 0.10000000000000001</scale>
              <uri>https://fuel.gazebosim.org/1.0/openrobotics/models/x3 uav/4/files/meshes/propeller_ccw.dae</uri>
            </mesh>
          </geometry>
          <material>
            <script>
              <name>Gazebo/Red</name>
              <uri>file://media/materials/scripts/gazebo.material</uri>
            </script>
          </material>
        </visual>
        <gravity>true</gravity>
        <velocity_decay/>
        <enable_wind>false</enable_wind>
      </link>
      <joint name='X3/rotor_1_joint' type='revolute'>
        <child>X3/rotor_1</child>
        <parent>X3/base_link</parent>
        <axis>
          <xyz>0 0 1</xyz>
          <limit>
            <lower>-10000000000000000</lower>
            <upper>10000000000000000</upper>
            <effort>inf</effort>
            <velocity>inf</velocity>
            <stiffness>100000000</stiffness>
            <dissipation>1</dissipation>
          </limit>
          <dynamics>
            <spring_reference>0</spring_reference>
            <spring_stiffness>0</spring_stiffness>
            <damping>0</damping>
            <friction>0</friction>
          </dynamics>
        </axis>
        <pose>1.3877787807814457e-17 -8.3266726846886741e-17 0 0 0 0</pose>
      </joint>
      <link name='X3/rotor_2'>
        <pose>0.13000000033504189 0.22000009186539424 0.023000404893187998 -1.4281829988050859e-06 -4.3610897539209234e-07 2.8449346822147183</pose>
        <inertial>
          <pose>0 0 0 0 0 0</pose>
          <mass>0.0050000000000000001</mass>
          <inertia>
            <ixx>9.7499999999999998e-07</ixx>
            <ixy>0</ixy>
            <ixz>0</ixz>
            <iyy>4.1704099999999999e-05</iyy>
            <iyz>0</iyz>
            <izz>4.2604100000000001e-05</izz>
          </inertia>
        </inertial>
        <collision name='X3/rotor_2_collision'>
          <pose>0 0 0 0 0 0</pose>
          <geometry>
            <cylinder>
              <length>0.0050000000000000001</length>
              <radius>0.10000000000000001</radius>
            </cylinder>
          </geometry>
          <surface>
            <contact>
              <ode/>
            </contact>
            <friction>
              <ode/>
            </friction>
            <bounce/>
          </surface>
        </collision>
        <visual name='X3/rotor_2_visual'>
          <pose>0 0 0 0 0 0</pose>
          <geometry>
            <mesh>
              <scale>0.10000000000000001 0.10000000000000001 0.10000000000000001</scale>
              <uri>https://fuel.gazebosim.org/1.0/openrobotics/models/x3 uav/4/files/meshes/propeller_cw.dae</uri>
            </mesh>
          </geometry>
          <material>
            <script>
              <name>Gazebo/Blue</name>
              <uri>file://media/materials/scripts/gazebo.material</uri>
            </script>
          </material>
        </visual>
        <gravity>true</gravity>
        <velocity_decay/>
        <enable_wind>false</enable_wind>
      </link>
      <joint name='X3/rotor_2_joint' type='revolute'>
        <child>X3/rotor_2</child>
        <parent>X3/base_link</parent>
        <axis>
          <xyz>0 0 1</xyz>
          <limit>
            <lower>-10000000000000000</lower>
            <upper>10000000000000000</upper>
            <effort>inf</effort>
            <velocity>inf</velocity>
            <stiffness>100000000</stiffness>
            <dissipation>1</dissipation>
          </limit>
          <dynamics>
            <spring_reference>0</spring_reference>
            <spring_stiffness>0</spring_stiffness>
            <damping>0</damping>
            <friction>0</friction>
          </dynamics>
        </axis>
        <pose>4.163336342344337e-17 -2.7755575615628914e-17 3.4694469519536142e-18 0 0 0</pose>
      </joint>
      <link name='X3/rotor_3'>
        <pose>-0.12999999966397077 -0.19999990813474861 0.02299977760061056 -1.4281768630358525e-06 -4.3612906849062269e-07 2.8449206131901548</pose>
        <inertial>
          <pose>0 0 0 0 0 0</pose>
          <mass>0.0050000000000000001</mass>
          <inertia>
            <ixx>9.7499999999999998e-07</ixx>
            <ixy>0</ixy>
            <ixz>0</ixz>
            <iyy>4.1704099999999999e-05</iyy>
            <iyz>0</iyz>
            <izz>4.2604100000000001e-05</izz>
          </inertia>
        </inertial>
        <collision name='X3/rotor_3_collision'>
          <pose>0 0 0 0 0 0</pose>
          <geometry>
            <cylinder>
              <length>0.0050000000000000001</length>
              <radius>0.10000000000000001</radius>
            </cylinder>
          </geometry>
          <surface>
            <contact>
              <ode/>
            </contact>
            <friction>
              <ode/>
            </friction>
            <bounce/>
          </surface>
        </collision>
        <visual name='X3/rotor_3_visual'>
          <pose>0 0 0 0 0 0</pose>
          <geometry>
            <mesh>
              <scale>0.10000000000000001 0.10000000000000001 0.10000000000000001</scale>
              <uri>https://fuel.gazebosim.org/1.0/openrobotics/models/x3 uav/4/files/meshes/propeller_cw.dae</uri>
            </mesh>
          </geometry>
          <material>
            <script>
              <name>Gazebo/Red</name>
              <uri>file://media/materials/scripts/gazebo.material</uri>
            </script>
          </material>
        </visual>
        <gravity>true</gravity>
        <velocity_decay/>
        <enable_wind>false</enable_wind>
      </link>
      <joint name='X3/rotor_3_joint' type='revolute'>
        <child>X3/rotor_3</child>
        <parent>X3/base_link</parent>
        <axis>
          <xyz>-5.2939559203393771e-23 -1.4693679385278594e-39 1</xyz>
          <limit>
            <lower>-10000000000000000</lower>
            <upper>10000000000000000</upper>
            <effort>inf</effort>
            <velocity>inf</velocity>
            <stiffness>100000000</stiffness>
            <dissipation>1</dissipation>
          </limit>
          <dynamics>
            <spring_reference>0</spring_reference>
            <spring_stiffness>0</spring_stiffness>
            <damping>0</damping>
            <friction>0</friction>
          </dynamics>
        </axis>
        <pose>2.7755575615628914e-17 1.3877787807814457e-16 0 -1.4693679385278594e-39 -5.2939559203393771e-23 5.5511151231257827e-17</pose>
      </joint>
      <plugin name='gz::sim::systems::MulticopterMotorModel' filename='gz-sim-multicopter-motor-model-system'>
        <robotNamespace>UAV_1</robotNamespace>
        <jointName>X3/rotor_0_joint</jointName>
        <linkName>X3/rotor_0</linkName>
        <turningDirection>ccw</turningDirection>
        <timeConstantUp>0.0125</timeConstantUp>
        <timeConstantDown>0.025</timeConstantDown>
        <maxRotVelocity>800.0</maxRotVelocity>
        <motorConstant>8.54858e-06</motorConstant>
        <momentConstant>0.016</momentConstant>
        <commandSubTopic>gazebo/command/motor_speed</commandSubTopic>
        <actuator_number>0</actuator_number>
        <rotorDragCoefficient>8.06428e-05</rotorDragCoefficient>
        <rollingMomentCoefficient>1e-06</rollingMomentCoefficient>
        <motorSpeedPubTopic>motor_speed/0</motorSpeedPubTopic>
        <rotorVelocitySlowdownSim>10</rotorVelocitySlowdownSim>
        <motorType>velocity</motorType>
      </plugin>
      <plugin name='gz::sim::systems::MulticopterMotorModel' filename='gz-sim-multicopter-motor-model-system'>
        <robotNamespace>UAV_1</robotNamespace>
        <jointName>X3/rotor_1_joint</jointName>
        <linkName>X3/rotor_1</linkName>
        <turningDirection>ccw</turningDirection>
        <timeConstantUp>0.0125</timeConstantUp>
        <timeConstantDown>0.025</timeConstantDown>
        <maxRotVelocity>800.0</maxRotVelocity>
        <motorConstant>8.54858e-06</motorConstant>
        <momentConstant>0.016</momentConstant>
        <commandSubTopic>gazebo/command/motor_speed</commandSubTopic>
        <actuator_number>1</actuator_number>
        <rotorDragCoefficient>8.06428e-05</rotorDragCoefficient>
        <rollingMomentCoefficient>1e-06</rollingMomentCoefficient>
        <motorSpeedPubTopic>motor_speed/1</motorSpeedPubTopic>
        <rotorVelocitySlowdownSim>10</rotorVelocitySlowdownSim>
        <motorType>velocity</motorType>
      </plugin>
      <plugin name='gz::sim::systems::MulticopterMotorModel' filename='gz-sim-multicopter-motor-model-system'>
        <robotNamespace>UAV_1</robotNamespace>
        <jointName>X3/rotor_2_joint</jointName>
        <linkName>X3/rotor_2</linkName>
        <turningDirection>cw</turningDirection>
        <timeConstantUp>0.0125</timeConstantUp>
        <timeConstantDown>0.025</timeConstantDown>
        <maxRotVelocity>800.0</maxRotVelocity>
        <motorConstant>8.54858e-06</motorConstant>
        <momentConstant>0.016</momentConstant>
        <commandSubTopic>gazebo/command/motor_speed</commandSubTopic>
        <actuator_number>2</actuator_number>
        <rotorDragCoefficient>8.06428e-05</rotorDragCoefficient>
        <rollingMomentCoefficient>1e-06</rollingMomentCoefficient>
        <motorSpeedPubTopic>motor_speed/2</motorSpeedPubTopic>
        <rotorVelocitySlowdownSim>10</rotorVelocitySlowdownSim>
        <motorType>velocity</motorType>
      </plugin>
      <plugin name='gz::sim::systems::MulticopterMotorModel' filename='gz-sim-multicopter-motor-model-system'>
        <robotNamespace>UAV_1</robotNamespace>
        <jointName>X3/rotor_3_joint</jointName>
        <linkName>X3/rotor_3</linkName>
        <turningDirection>cw</turningDirection>
        <timeConstantUp>0.0125</timeConstantUp>
        <timeConstantDown>0.025</timeConstantDown>
        <maxRotVelocity>800.0</maxRotVelocity>
        <motorConstant>8.54858e-06</motorConstant>
        <momentConstant>0.016</momentConstant>
        <commandSubTopic>gazebo/command/motor_speed</commandSubTopic>
        <actuator_number>3</actuator_number>
        <rotorDragCoefficient>8.06428e-05</rotorDragCoefficient>
        <rollingMomentCoefficient>1e-06</rollingMomentCoefficient>
        <motorSpeedPubTopic>motor_speed/3</motorSpeedPubTopic>
        <rotorVelocitySlowdownSim>10</rotorVelocitySlowdownSim>
        <motorType>velocity</motorType>
      </plugin>
      <plugin name='gz::sim::systems::MulticopterVelocityControl' filename='gz-sim-multicopter-control-system'>
        <robotNamespace>UAV_1</robotNamespace>
        <commandSubTopic>gazebo/command/twist</commandSubTopic>
        <enableSubTopic>enable</enableSubTopic>
        <comLinkName>X3/base_link</comLinkName>
        <velocityGain>2.7 2.7 2.7</velocityGain>
        <attitudeGain>2 3 0.15</attitudeGain>
        <angularRateGain>0.4 0.52 0.18</angularRateGain>
        <maximumLinearAcceleration>2 2 2</maximumLinearAcceleration>
        <rotorConfiguration>
          <rotor>
            <jointName>X3/rotor_0_joint</jointName>
            <forceConstant>8.54858e-06</forceConstant>
            <momentConstant>0.016</momentConstant>
            <direction>1</direction>
          </rotor>
          <rotor>
            <jointName>X3/rotor_1_joint</jointName>
            <forceConstant>8.54858e-06</forceConstant>
            <momentConstant>0.016</momentConstant>
            <direction>1</direction>
          </rotor>
          <rotor>
            <jointName>X3/rotor_2_joint</jointName>
            <forceConstant>8.54858e-06</forceConstant>
            <momentConstant>0.016</momentConstant>
            <direction>-1</direction>
          </rotor>
          <rotor>
            <jointName>X3/rotor_3_joint</jointName>
            <forceConstant>8.54858e-06</forceConstant>
            <momentConstant>0.016</momentConstant>
            <direction>-1</direction>
          </rotor>
        </rotorConfiguration>
      </plugin>
      <plugin name='gz::sim::systems::OdometryPublisher' filename='gz-sim-odometry-publisher-system'>
        <dimensions>3</dimensions>
      </plugin>
      <static>false</static>
      <self_collide>false</self_collide>
    </model>
    <model name='UAV_2'>
      <pose>-2.4157711801245196e-06 3 0.3285245262587268 4.3744994116032948e-15 1.0712389735201401e-06 -3.2893187470706874e-16</pose>
      <link name='base_link'>
        <pose>0 0 0 0 0 0</pose>
        <inertial>
          <pose>0 0 0 0 0 0</pose>
          <mass>3.4199999999999999</mass>
          <inertia>
            <ixx>0.074999999999999997</ixx>
            <ixy>0</ixy>
            <ixz>0</ixz>
            <iyy>0.074999999999999997</iyy>
            <iyz>0</iyz>
            <izz>0.14891599999999999</izz>
          </inertia>
        </inertial>
        <collision name='base_link_inertia_collision'>
          <pose>0 0 0 0 0 0</pose>
          <geometry>
            <box>
              <size>0.29999999999999999 0.29999999999999999 0.25</size>
            </box>
          </geometry>
          <surface>
            <friction>
              <ode/>
            </friction>
            <bounce/>
            <contact/>
          </surface>
        </collision>
        <visual name='base_link_inertia_visual'>
          <pose>0 0 0 0 0 0</pose>
          <geometry>
            <mesh>
              <scale>1 1 1</scale>
              <uri>https://fuel.gazebosim.org/1.0/openrobotics/models/x4 uav config 1/15/files/meshes/x4.dae</uri>
            </mesh>
          </geometry>
        </visual>
        <visual name='marker_visual_1'>
          <pose>-0.10000000000000001 0 0.076999999999999999 0 -0.10000000000000001 0</pose>
          <geometry>
            <mesh>
              <scale>1 1 1</scale>
              <uri>https://fuel.gazebosim.org/1.0/openrobotics/models/x4 uav config 1/15/files/meshes/led.dae</uri>
            </mesh>
          </geometry>
        </visual>
        <visual name='marker_visual_2'>
          <pose>-0.089999999999999997 0.058999999999999997 0.058999999999999997 -0.78539699999999935 -5.5511151231257827e-17 0.1999999999999999</pose>
          <geometry>
            <mesh>
              <scale>1 1 1</scale>
              <uri>https://fuel.gazebosim.org/1.0/openrobotics/models/x4 uav config 1/15/files/meshes/led.dae</uri>
            </mesh>
          </geometry>
        </visual>
        <visual name='marker_visual_3'>
          <pose>-0.089999999999999997 -0.058999999999999997 0.058999999999999997 0.78539699999999935 -5.5511151231257827e-17 -0.1999999999999999</pose>
          <geometry>
            <mesh>
              <scale>1 1 1</scale>
              <uri>https://fuel.gazebosim.org/1.0/openrobotics/models/x4 uav config 1/15/files/meshes/led.dae</uri>
            </mesh>
          </geometry>
        </visual>
        <visual name='downward_flashlight_visual'>
          <pose>-0.043704 0 0.10291400000000001 -0.19999999999999993 0.00015799999999999988 -1.5700199999999997</pose>
          <geometry>
            <mesh>
              <scale>0.01 0.01 0.01</scale>
              <uri>https://fuel.gazebosim.org/1.0/openrobotics/models/x4 uav config 1/15/files/meshes/spotlight.dae</uri>
            </mesh>
          </geometry>
        </visual>
        <visual name='left_flashlight_visual'>
          <pose>-0.071984999999999993 0.090826000000000004 0.066101999999999994 0.059999999999999984 -4.799999999999826e-05 -1.27</pose>
          <geometry>
            <mesh>
              <scale>0.01 0.01 0.01</scale>
              <uri>https://fuel.gazebosim.org/1.0/openrobotics/models/x4 uav config 1/15/files/meshes/spotlight.dae</uri>
            </mesh>
          </geometry>
        </visual>
        <visual name='right_flashlight_visual'>
          <pose>-0.071984999999999993 -0.090826000000000004 0.066101999999999994 0.059999999999999998 -4.8000000000005199e-05 -1.8699999999999999</pose>
          <geometry>
            <mesh>
              <scale>0.01 0.01 0.01</scale>
              <uri>https://fuel.gazebosim.org/1.0/openrobotics/models/x4 uav config 1/15/files/meshes/spotlight.dae</uri>
            </mesh>
          </geometry>
        </visual>
        <light name='right_light_source' type='spot'>
          <pose>0 -0.11 0.070000000000000007 3.1315900000000001 -1.5107900000000036 2.8415899999999996</pose>
          <cast_shadows>true</cast_shadows>
          <intensity>1</intensity>
          <direction>0 0 -1</direction>
          <diffuse>0.800000012 0.800000012 0.5 1</diffuse>
          <specular>0.800000012 0.800000012 0.5 1</specular>
          <attenuation>
            <range>15</range>
            <linear>0</linear>
            <constant>0.10000000149011612</constant>
            <quadratic>0.0099999997764825821</quadratic>
          </attenuation>
          <spot>
            <inner_angle>1</inner_angle>
            <outer_angle>1.1000000238418579</outer_angle>
            <falloff>1</falloff>
          </spot>
        </light>
        <light name='downward_flashlight_source' type='spot'>
          <pose>0.029999999999999999 0 0.089999999999999997 -0.010000000000000007 -1.3708 8.7318707102629613e-18</pose>
          <cast_shadows>true</cast_shadows>
          <intensity>1</intensity>
          <direction>0 0 -1</direction>
          <diffuse>0.800000012 0.800000012 0.5 1</diffuse>
          <specular>0.800000012 0.800000012 0.5 1</specular>
          <attenuation>
            <range>15</range>
            <linear>0</linear>
            <constant>0.10000000149011612</constant>
            <quadratic>0.0099999997764825821</quadratic>
          </attenuation>
          <spot>
            <inner_angle>1</inner_angle>
            <outer_angle>1.1000000238418579</outer_angle>
            <falloff>1</falloff>
          </spot>
        </light>
        <light name='left_flashlight_source' type='spot'>
          <pose>0 0.11 0.070000000000000007 3.1315899999999997 -1.5107900000000092 -2.8415899999999992</pose>
          <cast_shadows>true</cast_shadows>
          <intensity>1</intensity>
          <direction>0 0 -1</direction>
          <diffuse>0.800000012 0.800000012 0.5 1</diffuse>
          <specular>0.800000012 0.800000012 0.5 1</specular>
          <attenuation>
            <range>15</range>
            <linear>0</linear>
            <constant>0.10000000149011612</constant>
            <quadratic>0.0099999997764825821</quadratic>
          </attenuation>
          <spot>
            <inner_angle>1</inner_angle>
            <outer_angle>1.1000000238418579</outer_angle>
            <falloff>1</falloff>
          </spot>
        </light>
        <sensor name='imu_sensor' type='imu'>
          <pose>0 0 0 0 0 0</pose>
          <topic>__default__</topic>
          <update_rate>250</update_rate>
          <enable_metrics>false</enable_metrics>
          <imu>
            <orientation_reference_frame>
              <localization>CUSTOM</localization>
              <custom_rpy>0 0 0</custom_rpy>
              <grav_dir_x>1 0 0</grav_dir_x>
            </orientation_reference_frame>
            <angular_velocity>
              <x>
                <noise type='gaussian'>
                  <mean>0</mean>
                  <stddev>0.0089999999999999993</stddev>
                  <bias_mean>0.00075000000000000002</bias_mean>
                  <bias_stddev>0.0050000000000000001</bias_stddev>
                  <dynamic_bias_stddev>2.0000000000000002e-05</dynamic_bias_stddev>
                  <dynamic_bias_correlation_time>400</dynamic_bias_correlation_time>
                  <precision>0.00025000000000000001</precision>
                </noise>
              </x>
              <y>
                <noise type='gaussian'>
                  <mean>0</mean>
                  <stddev>0.0089999999999999993</stddev>
                  <bias_mean>0.00075000000000000002</bias_mean>
                  <bias_stddev>0.0050000000000000001</bias_stddev>
                  <dynamic_bias_stddev>2.0000000000000002e-05</dynamic_bias_stddev>
                  <dynamic_bias_correlation_time>400</dynamic_bias_correlation_time>
                  <precision>0.00025000000000000001</precision>
                </noise>
              </y>
              <z>
                <noise type='gaussian'>
                  <mean>0</mean>
                  <stddev>0.0089999999999999993</stddev>
                  <bias_mean>0.00075000000000000002</bias_mean>
                  <bias_stddev>0.0050000000000000001</bias_stddev>
                  <dynamic_bias_stddev>2.0000000000000002e-05</dynamic_bias_stddev>
                  <dynamic_bias_correlation_time>400</dynamic_bias_correlation_time>
                  <precision>0.00025000000000000001</precision>
                </noise>
              </z>
            </angular_velocity>
            <linear_acceleration>
              <x>
                <noise type='gaussian'>
                  <mean>0</mean>
                  <stddev>0.021000000000000001</stddev>
                  <bias_mean>0.050000000000000003</bias_mean>
                  <bias_stddev>0.0074999999999999997</bias_stddev>
                  <dynamic_bias_stddev>0.00037500000000000001</dynamic_bias_stddev>
                  <dynamic_bias_correlation_time>175</dynamic_bias_correlation_time>
                  <precision>0.0050000000000000001</precision>
                </noise>
              </x>
              <y>
                <noise type='gaussian'>
                  <mean>0</mean>
                  <stddev>0.021000000000000001</stddev>
                  <bias_mean>0.050000000000000003</bias_mean>
                  <bias_stddev>0.0074999999999999997</bias_stddev>
                  <dynamic_bias_stddev>0.00037500000000000001</dynamic_bias_stddev>
                  <dynamic_bias_correlation_time>175</dynamic_bias_correlation_time>
                  <precision>0.0050000000000000001</precision>
                </noise>
              </y>
              <z>
                <noise type='gaussian'>
                  <mean>0</mean>
                  <stddev>0.021000000000000001</stddev>
                  <bias_mean>0.050000000000000003</bias_mean>
                  <bias_stddev>0.0074999999999999997</bias_stddev>
                  <dynamic_bias_stddev>0.00037500000000000001</dynamic_bias_stddev>
                  <dynamic_bias_correlation_time>175</dynamic_bias_correlation_time>
                  <precision>0.0050000000000000001</precision>
                </noise>
              </z>
            </linear_acceleration>
            <enable_orientation>true</enable_orientation>
          </imu>
        </sensor>
        <sensor name='air_pressure' type='air_pressure'>
          <pose>0 0 0 0 0 0</pose>
          <topic>__default__</topic>
          <update_rate>20</update_rate>
          <enable_metrics>false</enable_metrics>
          <air_pressure>
            <reference_altitude>0</reference_altitude>
            <pressure>
              <noise type='none'>
                <mean>0</mean>
                <stddev>0</stddev>
                <bias_mean>0</bias_mean>
                <bias_stddev>0</bias_stddev>
                <dynamic_bias_stddev>0</dynamic_bias_stddev>
                <dynamic_bias_correlation_time>0</dynamic_bias_correlation_time>
                <precision>0</precision>
              </noise>
            </pressure>
          </air_pressure>
        </sensor>
        <sensor name='magnetometer' type='magnetometer'>
          <pose>0 0 0 0 0 0</pose>
          <topic>__default__</topic>
          <update_rate>20</update_rate>
          <enable_metrics>false</enable_metrics>
          <magnetometer>
            <x>
              <noise type='gaussian'>
                <mean>8.0000000000000002e-08</mean>
                <stddev>0</stddev>
                <bias_mean>3.9999999999999998e-07</bias_mean>
                <bias_stddev>0</bias_stddev>
                <dynamic_bias_stddev>0</dynamic_bias_stddev>
                <dynamic_bias_correlation_time>0</dynamic_bias_correlation_time>
                <precision>0</precision>
              </noise>
            </x>
            <y>
              <noise type='gaussian'>
                <mean>8.0000000000000002e-08</mean>
                <stddev>0</stddev>
                <bias_mean>3.9999999999999998e-07</bias_mean>
                <bias_stddev>0</bias_stddev>
                <dynamic_bias_stddev>0</dynamic_bias_stddev>
                <dynamic_bias_correlation_time>0</dynamic_bias_correlation_time>
                <precision>0</precision>
              </noise>
            </y>
            <z>
              <noise type='gaussian'>
                <mean>8.0000000000000002e-08</mean>
                <stddev>0</stddev>
                <bias_mean>3.9999999999999998e-07</bias_mean>
                <bias_stddev>0</bias_stddev>
                <dynamic_bias_stddev>0</dynamic_bias_stddev>
                <dynamic_bias_correlation_time>0</dynamic_bias_correlation_time>
                <precision>0</precision>
              </noise>
            </z>
          </magnetometer>
        </sensor>
        <visual name='camera_mount_base_visual'>
          <pose>0.050000000000000003 0 -0.029999999999999999 0 0 0</pose>
          <geometry>
            <box>
              <size>0.059999999999999998 0.059999999999999998 0.0060000000000000001</size>
            </box>
          </geometry>
        </visual>
        <visual name='camera_mount_arm_visual'>
          <pose>0.080000000000000002 0 -0.040000000000000001 0 0 0</pose>
          <geometry>
            <cylinder>
              <radius>0.0050000000000000001</radius>
              <length>0.080000000000000002</length>
            </cylinder>
          </geometry>
        </visual>
        <visual name='camera_mount_arm2_visual'>
          <pose>0.080000000000000002 0 -0.080000000000000002 0 1.5700000000008241 0</pose>
          <geometry>
            <cylinder>
              <radius>0.01</radius>
              <length>0.025000000000000001</length>
            </cylinder>
          </geometry>
        </visual>
        <visual name='camera_visual'>
          <pose>0.10000000000000001 0 -0.080000000000000002 0 0 0</pose>
          <geometry>
            <box>
              <size>0.02 0.025000000000000001 0.025000000000000001</size>
            </box>
          </geometry>
        </visual>
        <sensor name='camera_front' type='camera'>
          <pose>0.10000000000000001 0 -0.080000000000000002 0 0 0</pose>
          <topic>__default__</topic>
          <update_rate>20</update_rate>
          <enable_metrics>false</enable_metrics>
          <camera name='__default__'>
            <pose>0 0 0 0 0 0</pose>
            <horizontal_fov>2</horizontal_fov>
            <image>
              <width>1280</width>
              <height>960</height>
              <format>RGB_INT8</format>
              <anti_aliasing>4</anti_aliasing>
            </image>
            <camera_info_topic>__default__</camera_info_topic>
            <trigger_topic></trigger_topic>
            <triggered>false</triggered>
            <clip>
              <near>0.02</near>
              <far>300</far>
            </clip>
            <save enabled='false'>
              <path>__default__</path>
            </save>
            <visibility_mask>4294967295</visibility_mask>
            <noise>
              <type>none</type>
              <mean>0</mean>
              <stddev>0</stddev>
            </noise>
            <distortion>
              <k1>0</k1>
              <k2>0</k2>
              <k3>0</k3>
              <p1>0</p1>
              <p2>0</p2>
              <center>0.5 0.5</center>
            </distortion>
            <lens>
              <type>stereographic</type>
              <scale_to_hfov>true</scale_to_hfov>
              <cutoff_angle>1.5707963267948966</cutoff_angle>
              <env_texture_size>256</env_texture_size>
            </lens>
            <optical_frame_id></optical_frame_id>
          </camera>
        </sensor>
        <enable_wind>false</enable_wind>
      </link>
      <link name='rotor_0'>
        <pose>0.24699999999999989 0.15059999999999985 0.028000000000000025 0.087267000000000053 -2.7433610938487618e-12 0.52359900003135662</pose>
        <inertial>
          <pose>0 0 0 0 0 0</pose>
          <mass>0.0050000000000000001</mass>
          <inertia>
            <ixx>9.7499999999999998e-07</ixx>
            <ixy>0</ixy>
            <ixz>0</ixz>
            <iyy>8.1354500000000002e-05</iyy>
            <iyz>0</iyz>
            <izz>8.2254499999999997e-05</izz>
          </inertia>
        </inertial>
        <collision name='rotor_0_collision'>
          <pose>0 0 0 0 0 0</pose>
          <geometry>
            <cylinder>
              <length>0.0050000000000000001</length>
              <radius>0.13969999999999999</radius>
            </cylinder>
          </geometry>
          <surface>
            <contact>
              <ode/>
            </contact>
            <friction>
              <ode/>
            </friction>
            <bounce/>
          </surface>
        </collision>
        <visual name='rotor_0_visual'>
          <pose>0 0 0 0 0 0</pose>
          <geometry>
            <mesh>
              <scale>1 1 1</scale>
              <uri>https://fuel.gazebosim.org/1.0/openrobotics/models/x4 uav config 1/15/files/meshes/neo11_propeller_ccw.dae</uri>
            </mesh>
          </geometry>
          <material>
            <diffuse>1 0 0 1</diffuse>
            <script>
              <name>Gazebo/Red</name>
              <uri>file://media/materials/scripts/gazebo.material</uri>
            </script>
          </material>
          <cast_shadows>false</cast_shadows>
        </visual>
        <gravity>true</gravity>
        <velocity_decay/>
        <enable_wind>false</enable_wind>
      </link>
      <joint name='rotor_0_joint' type='revolute'>
        <child>rotor_0</child>
        <parent>base_link</parent>
        <axis>
          <xyz>1.3548818325950784e-07 5.7496570800980029e-07 0.99999999999982558</xyz>
          <limit>
            <lower>-10000000000000000</lower>
            <upper>10000000000000000</upper>
            <effort>inf</effort>
            <velocity>inf</velocity>
            <stiffness>100000000</stiffness>
            <dissipation>1</dissipation>
          </limit>
          <dynamics>
            <spring_reference>0</spring_reference>
            <spring_stiffness>0</spring_stiffness>
            <damping>0</damping>
            <friction>0</friction>
          </dynamics>
        </axis>
        <pose>-1.6653345369377348e-16 -8.6736173798840355e-17 0 -1.474514954580286e-17 -3.4694469519536142e-18 2.5578757073892976e-35</pose>
      </joint>
      <link name='rotor_1'>
        <pose>-0.00066999999999999872 0.28929000000000071 0.027999999999999969 -3.1710593786359023e-18 -0.087267000000000011 3.6383679318776486e-17</pose>
        <inertial>
          <pose>0 0 0 0 0 0</pose>
          <mass>0.0050000000000000001</mass>
          <inertia>
            <ixx>9.7499999999999998e-07</ixx>
            <ixy>0</ixy>
            <ixz>0</ixz>
            <iyy>8.1354500000000002e-05</iyy>
            <iyz>0</iyz>
            <izz>8.2254499999999997e-05</izz>
          </inertia>
        </inertial>
        <collision name='rotor_1_collision'>
          <pose>0 0 0 0 0 0</pose>
          <geometry>
            <cylinder>
              <length>0.0050000000000000001</length>
              <radius>0.13969999999999999</radius>
            </cylinder>
          </geometry>
          <surface>
            <contact>
              <ode/>
            </contact>
            <friction>
              <ode/>
            </friction>
            <bounce/>
          </surface>
        </collision>
        <visual name='rotor_1_visual'>
          <pose>0 0 0 0 0 0</pose>
          <geometry>
            <mesh>
              <scale>1 1 1</scale>
              <uri>https://fuel.gazebosim.org/1.0/openrobotics/models/x4 uav config 1/15/files/meshes/neo11_propeller_cw.dae</uri>
            </mesh>
          </geometry>
          <material>
            <diffuse>0 0 1 1</diffuse>
            <script>
              <name>Gazebo/Blue</name>
              <uri>file://media/materials/scripts/gazebo.material</uri>
            </script>
          </material>
          <cast_shadows>false</cast_shadows>
        </visual>
        <gravity>true</gravity>
        <velocity_decay/>
        <enable_wind>false</enable_wind>
      </link>
      <joint name='rotor_1_joint' type='revolute'>
        <child>rotor_1</child>
        <parent>base_link</parent>
        <axis>
          <xyz>3.0743997701202647e-07 0 0.99999999999995282</xyz>
          <limit>
            <lower>-10000000000000000</lower>
            <upper>10000000000000000</upper>
            <effort>inf</effort>
            <velocity>inf</velocity>
            <stiffness>100000000</stiffness>
            <dissipation>1</dissipation>
          </limit>
          <dynamics>
            <spring_reference>0</spring_reference>
            <spring_stiffness>0</spring_stiffness>
            <damping>0</damping>
            <friction>0</friction>
          </dynamics>
        </axis>
        <pose>4.3368086899420177e-19 0 6.9388939039072284e-18 0 2.5445528161417262e-36 0</pose>
      </joint>
      <link name='rotor_2'>
        <pose>-0.25009999999999999 0.14540000000000042 0.02800000000000008 0.087267000000000025 -2.6170038358586112e-13 2.6179900000029908</pose>
        <inertial>
          <pose>0 0 0 0 0 0</pose>
          <mass>0.0050000000000000001</mass>
          <inertia>
            <ixx>9.7499999999999998e-07</ixx>
            <ixy>0</ixy>
            <ixz>0</ixz>
            <iyy>8.1354500000000002e-05</iyy>
            <iyz>0</iyz>
            <izz>8.2254499999999997e-05</izz>
          </inertia>
        </inertial>
        <collision name='rotor_2_collision'>
          <pose>0 0 0 0 0 0</pose>
          <geometry>
            <cylinder>
              <length>0.0050000000000000001</length>
              <radius>0.13969999999999999</radius>
            </cylinder>
          </geometry>
          <surface>
            <contact>
              <ode/>
            </contact>
            <friction>
              <ode/>
            </friction>
            <bounce/>
          </surface>
        </collision>
        <visual name='rotor_2_visual'>
          <pose>0 0 0 0 0 0</pose>
          <geometry>
            <mesh>
              <scale>1 1 1</scale>
              <uri>https://fuel.gazebosim.org/1.0/openrobotics/models/x4 uav config 1/15/files/meshes/neo11_propeller_ccw.dae</uri>
            </mesh>
          </geometry>
          <material>
            <diffuse>0 0 1 1</diffuse>
            <script>
              <name>Gazebo/Blue</name>
              <uri>file://media/materials/scripts/gazebo.material</uri>
            </script>
          </material>
          <cast_shadows>false</cast_shadows>
        </visual>
        <gravity>true</gravity>
        <velocity_decay/>
        <enable_wind>false</enable_wind>
      </link>
      <joint name='rotor_2_joint' type='revolute'>
        <child>rotor_2</child>
        <parent>base_link</parent>
        <axis>
          <xyz>1.8294301218357847e-07 5.749657943990295e-07 0.99999999999981803</xyz>
          <limit>
            <lower>-10000000000000000</lower>
            <upper>10000000000000000</upper>
            <effort>inf</effort>
            <velocity>inf</velocity>
            <stiffness>100000000</stiffness>
            <dissipation>1</dissipation>
          </limit>
          <dynamics>
            <spring_reference>0</spring_reference>
            <spring_stiffness>0</spring_stiffness>
            <damping>0</damping>
            <friction>0</friction>
          </dynamics>
        </axis>
        <pose>3.3306690738754696e-16 -4.163336342344337e-17 6.9388939039072284e-18 0 0 0</pose>
      </joint>
      <link name='rotor_3'>
        <pose>-0.25010000000000004 -0.14539999999999953 0.028000000000000136 -0.087266999999999997 -2.6170385303281307e-13 -2.6179900000029908</pose>
        <inertial>
          <pose>0 0 0 0 0 0</pose>
          <mass>0.0050000000000000001</mass>
          <inertia>
            <ixx>9.7499999999999998e-07</ixx>
            <ixy>0</ixy>
            <ixz>0</ixz>
            <iyy>8.1354500000000002e-05</iyy>
            <iyz>0</iyz>
            <izz>8.2254499999999997e-05</izz>
          </inertia>
        </inertial>
        <collision name='rotor_3_collision'>
          <pose>0 0 0 0 0 0</pose>
          <geometry>
            <cylinder>
              <length>0.0050000000000000001</length>
              <radius>0.13969999999999999</radius>
            </cylinder>
          </geometry>
          <surface>
            <contact>
              <ode/>
            </contact>
            <friction>
              <ode/>
            </friction>
            <bounce/>
          </surface>
        </collision>
        <visual name='rotor_3_visual'>
          <pose>0 0 0 0 0 0</pose>
          <geometry>
            <mesh>
              <scale>1 1 1</scale>
              <uri>https://fuel.gazebosim.org/1.0/openrobotics/models/x4 uav config 1/15/files/meshes/neo11_propeller_cw.dae</uri>
            </mesh>
          </geometry>
          <material>
            <diffuse>0 0 1 1</diffuse>
            <script>
              <name>Gazebo/Blue</name>
              <uri>file://media/materials/scripts/gazebo.material</uri>
            </script>
          </material>
          <cast_shadows>false</cast_shadows>
        </visual>
        <gravity>true</gravity>
        <velocity_decay/>
        <enable_wind>false</enable_wind>
      </link>
      <joint name='rotor_3_joint' type='revolute'>
        <child>rotor_3</child>
        <parent>base_link</parent>
        <axis>
          <xyz>1.8294301218010903e-07 -5.749657943990295e-07 0.99999999999981803</xyz>
          <limit>
            <lower>-10000000000000000</lower>
            <upper>10000000000000000</upper>
            <effort>inf</effort>
            <velocity>inf</velocity>
            <stiffness>100000000</stiffness>
            <dissipation>1</dissipation>
          </limit>
          <dynamics>
            <spring_reference>0</spring_reference>
            <spring_stiffness>0</spring_stiffness>
            <damping>0</damping>
            <friction>0</friction>
          </dynamics>
        </axis>
        <pose>3.3306690738754696e-16 4.163336342344337e-17 1.0408340855860843e-17 0 -3.469446951953615e-18 0</pose>
      </joint>
      <link name='rotor_4'>
        <pose>-0.00066999999999999959 -0.28928999999999983 0.028000000000000025 8.4189868478409986e-18 0.087267000000000039 -3.1415899999999999</pose>
        <inertial>
          <pose>0 0 0 0 0 0</pose>
          <mass>0.0050000000000000001</mass>
          <inertia>
            <ixx>9.7499999999999998e-07</ixx>
            <ixy>0</ixy>
            <ixz>0</ixz>
            <iyy>8.1354500000000002e-05</iyy>
            <iyz>0</iyz>
            <izz>8.2254499999999997e-05</izz>
          </inertia>
        </inertial>
        <collision name='rotor_4_collision'>
          <pose>0 0 0 0 0 0</pose>
          <geometry>
            <cylinder>
              <length>0.0050000000000000001</length>
              <radius>0.13969999999999999</radius>
            </cylinder>
          </geometry>
          <surface>
            <contact>
              <ode/>
            </contact>
            <friction>
              <ode/>
            </friction>
            <bounce/>
          </surface>
        </collision>
        <visual name='rotor_4_visual'>
          <pose>0 0 0 0 0 0</pose>
          <geometry>
            <mesh>
              <scale>1 1 1</scale>
              <uri>https://fuel.gazebosim.org/1.0/openrobotics/models/x4 uav config 1/15/files/meshes/neo11_propeller_ccw.dae</uri>
            </mesh>
          </geometry>
          <material>
            <diffuse>0 0 1 1</diffuse>
            <script>
              <name>Gazebo/Blue</name>
              <uri>file://media/materials/scripts/gazebo.material</uri>
            </script>
          </material>
          <cast_shadows>false</cast_shadows>
        </visual>
        <gravity>true</gravity>
        <velocity_decay/>
        <enable_wind>false</enable_wind>
      </link>
      <joint name='rotor_4_joint' type='revolute'>
        <child>rotor_4</child>
        <parent>base_link</parent>
        <axis>
          <xyz>-3.0744028273188562e-07 -2.3127619728550544e-07 0.99999999999992606</xyz>
          <limit>
            <lower>-10000000000000000</lower>
            <upper>10000000000000000</upper>
            <effort>inf</effort>
            <velocity>inf</velocity>
            <stiffness>100000000</stiffness>
            <dissipation>1</dissipation>
          </limit>
          <dynamics>
            <spring_reference>0</spring_reference>
            <spring_stiffness>0</spring_stiffness>
            <damping>0</damping>
            <friction>0</friction>
          </dynamics>
        </axis>
        <pose>-1.0842021724855044e-18 2.2204460492503131e-16 6.9388939039072284e-18 0 0 -4.2351647362715026e-22</pose>
      </joint>
      <link name='rotor_5'>
        <pose>0.24699999999999989 -0.15059999999999896 0.02800000000000008 -0.087267000000000081 -2.7433610938487618e-12 -0.52359900003135662</pose>
        <inertial>
          <pose>0 0 0 0 0 0</pose>
          <mass>0.0050000000000000001</mass>
          <inertia>
            <ixx>9.7499999999999998e-07</ixx>
            <ixy>0</ixy>
            <ixz>0</ixz>
            <iyy>8.1354500000000002e-05</iyy>
            <iyz>0</iyz>
            <izz>8.2254499999999997e-05</izz>
          </inertia>
        </inertial>
        <collision name='rotor_5_collision'>
          <pose>0 0 0 0 0 0</pose>
          <geometry>
            <cylinder>
              <length>0.0050000000000000001</length>
              <radius>0.13969999999999999</radius>
            </cylinder>
          </geometry>
          <surface>
            <contact>
              <ode/>
            </contact>
            <friction>
              <ode/>
            </friction>
            <bounce/>
          </surface>
        </collision>
        <visual name='rotor_5_visual'>
          <pose>0 0 0 0 0 0</pose>
          <geometry>
            <mesh>
              <scale>1 1 1</scale>
              <uri>https://fuel.gazebosim.org/1.0/openrobotics/models/x4 uav config 1/15/files/meshes/neo11_propeller_cw.dae</uri>
            </mesh>
          </geometry>
          <material>
            <diffuse>1 0 0 1</diffuse>
            <script>
              <name>Gazebo/Red</name>
              <uri>file://media/materials/scripts/gazebo.material</uri>
            </script>
          </material>
          <cast_shadows>false</cast_shadows>
        </visual>
        <gravity>true</gravity>
        <velocity_decay/>
        <enable_wind>false</enable_wind>
      </link>
      <joint name='rotor_5_joint' type='revolute'>
        <child>rotor_5</child>
        <parent>base_link</parent>
        <axis>
          <xyz>1.354881832560384e-07 -5.7496570800980029e-07 0.99999999999982558</xyz>
          <limit>
            <lower>-10000000000000000</lower>
            <upper>10000000000000000</upper>
            <effort>inf</effort>
            <velocity>inf</velocity>
            <stiffness>100000000</stiffness>
            <dissipation>1</dissipation>
          </limit>
          <dynamics>
            <spring_reference>0</spring_reference>
            <spring_stiffness>0</spring_stiffness>
            <damping>0</damping>
            <friction>0</friction>
          </dynamics>
        </axis>
        <pose>-1.6653345369377348e-16 8.6736173798840355e-17 3.4694469519536142e-18 1.474514954580286e-17 -6.9388939039072284e-18 -5.1157514147785952e-35</pose>
      </joint>
      <plugin name='gz::sim::systems::MulticopterMotorModel' filename='gz-sim-multicopter-motor-model-system'>
        <robotNamespace>UAV_2</robotNamespace>
        <jointName>rotor_0_joint</jointName>
        <linkName>rotor_0</linkName>
        <turningDirection>ccw</turningDirection>
        <timeConstantUp>0.0182</timeConstantUp>
        <timeConstantDown>0.0182</timeConstantDown>
        <maxRotVelocity>1000.0</maxRotVelocity>
        <motorConstant>1.269e-05</motorConstant>
        <momentConstant>0.016754</momentConstant>
        <commandSubTopic>command/motor_speed</commandSubTopic>
        <actuator_number>0</actuator_number>
        <rotorDragCoefficient>2.0673e-04</rotorDragCoefficient>
        <rotorDragCoefficient>0</rotorDragCoefficient>
        <rollingMomentCoefficient>0</rollingMomentCoefficient>
        <motorSpeedPubTopic>motor_speed/0</motorSpeedPubTopic>
        <rotorVelocitySlowdownSim>2</rotorVelocitySlowdownSim>
        <motorType>velocity</motorType>
      </plugin>
      <plugin name='gz::sim::systems::MulticopterMotorModel' filename='gz-sim-multicopter-motor-model-system'>
        <robotNamespace>UAV_2</robotNamespace>
        <jointName>rotor_1_joint</jointName>
        <linkName>rotor_1</linkName>
        <turningDirection>cw</turningDirection>
        <timeConstantUp>0.0182</timeConstantUp>
        <timeConstantDown>0.0182</timeConstantDown>
        <maxRotVelocity>1000.0</maxRotVelocity>
        <motorConstant>1.269e-05</motorConstant>
        <momentConstant>0.016754</momentConstant>
        <commandSubTopic>command/motor_speed</commandSubTopic>
        <actuator_number>1</actuator_number>
        <rotorDragCoefficient>2.0673e-04</rotorDragCoefficient>
        <rotorDragCoefficient>0</rotorDragCoefficient>
        <rollingMomentCoefficient>0</rollingMomentCoefficient>
        <motorSpeedPubTopic>motor_speed/1</motorSpeedPubTopic>
        <rotorVelocitySlowdownSim>2</rotorVelocitySlowdownSim>
        <motorType>velocity</motorType>
      </plugin>
      <plugin name='gz::sim::systems::MulticopterMotorModel' filename='gz-sim-multicopter-motor-model-system'>
        <robotNamespace>UAV_2</robotNamespace>
        <jointName>rotor_2_joint</jointName>
        <linkName>rotor_2</linkName>
        <turningDirection>ccw</turningDirection>
        <timeConstantUp>0.0182</timeConstantUp>
        <timeConstantDown>0.0182</timeConstantDown>
        <maxRotVelocity>1000.0</maxRotVelocity>
        <motorConstant>1.269e-05</motorConstant>
        <momentConstant>0.016754</momentConstant>
        <commandSubTopic>command/motor_speed</commandSubTopic>
        <actuator_number>2</actuator_number>
        <rotorDragCoefficient>2.0673e-04</rotorDragCoefficient>
        <rotorDragCoefficient>0</rotorDragCoefficient>
        <rollingMomentCoefficient>0</rollingMomentCoefficient>
        <motorSpeedPubTopic>motor_speed/2</motorSpeedPubTopic>
        <rotorVelocitySlowdownSim>2</rotorVelocitySlowdownSim>
        <motorType>velocity</motorType>
      </plugin>
      <plugin name='gz::sim::systems::MulticopterMotorModel' filename='gz-sim-multicopter-motor-model-system'>
        <robotNamespace>UAV_2</robotNamespace>
        <jointName>rotor_3_joint</jointName>
        <linkName>rotor_3</linkName>
        <turningDirection>cw</turningDirection>
        <timeConstantUp>0.0182</timeConstantUp>
        <timeConstantDown>0.0182</timeConstantDown>
        <maxRotVelocity>1000.0</maxRotVelocity>
        <motorConstant>1.269e-05</motorConstant>
        <momentConstant>0.016754</momentConstant>
        <commandSubTopic>command/motor_speed</commandSubTopic>
        <actuator_number>3</actuator_number>
        <rotorDragCoefficient>2.0673e-04</rotorDragCoefficient>
        <rotorDragCoefficient>0</rotorDragCoefficient>
        <rollingMomentCoefficient>0</rollingMomentCoefficient>
        <motorSpeedPubTopic>motor_speed/3</motorSpeedPubTopic>
        <rotorVelocitySlowdownSim>2</rotorVelocitySlowdownSim>
        <motorType>velocity</motorType>
      </plugin>
      <plugin name='gz::sim::systems::MulticopterMotorModel' filename='gz-sim-multicopter-motor-model-system'>
        <robotNamespace>UAV_2</robotNamespace>
        <jointName>rotor_4_joint</jointName>
        <linkName>rotor_4</linkName>
        <turningDirection>ccw</turningDirection>
        <timeConstantUp>0.0182</timeConstantUp>
        <timeConstantDown>0.0182</timeConstantDown>
        <maxRotVelocity>1000.0</maxRotVelocity>
        <motorConstant>1.269e-05</motorConstant>
        <momentConstant>0.016754</momentConstant>
        <commandSubTopic>command/motor_speed</commandSubTopic>
        <actuator_number>4</actuator_number>
        <rotorDragCoefficient>2.0673e-04</rotorDragCoefficient>
        <rotorDragCoefficient>0</rotorDragCoefficient>
        <rollingMomentCoefficient>0</rollingMomentCoefficient>
        <motorSpeedPubTopic>motor_speed/4</motorSpeedPubTopic>
        <rotorVelocitySlowdownSim>2</rotorVelocitySlowdownSim>
        <motorType>velocity</motorType>
      </plugin>
      <plugin name='gz::sim::systems::MulticopterMotorModel' filename='gz-sim-multicopter-motor-model-system'>
        <robotNamespace>UAV_2</robotNamespace>
        <jointName>rotor_5_joint</jointName>
        <linkName>rotor_5</linkName>
        <turningDirection>cw</turningDirection>
        <timeConstantUp>0.0182</timeConstantUp>
        <timeConstantDown>0.0182</timeConstantDown>
        <maxRotVelocity>1000.0</maxRotVelocity>
        <motorConstant>1.269e-05</motorConstant>
        <momentConstant>0.016754</momentConstant>
        <commandSubTopic>command/motor_speed</commandSubTopic>
        <actuator_number>5</actuator_number>
        <rotorDragCoefficient>2.0673e-04</rotorDragCoefficient>
        <rotorDragCoefficient>0</rotorDragCoefficient>
        <rollingMomentCoefficient>0</rollingMomentCoefficient>
        <motorSpeedPubTopic>motor_speed/5</motorSpeedPubTopic>
        <rotorVelocitySlowdownSim>2</rotorVelocitySlowdownSim>
        <motorType>velocity</motorType>
      </plugin>
      <plugin name='gz::sim::systems::MulticopterVelocityControl' filename='gz-sim-multicopter-control-system'>
        <robotNamespace>UAV_2</robotNamespace>
        <commandSubTopic>gazebo/command/twist</commandSubTopic>
        <enableSubTopic>enable</enableSubTopic>
        <comLinkName>base_link</comLinkName>
        <velocityGain>6 6 10</velocityGain>
        <attitudeGain>4 4 2</attitudeGain>
        <angularRateGain>0.7 0.7 0.7</angularRateGain>
        <maximumLinearAcceleration>1 1 2</maximumLinearAcceleration>
        <maximumLinearVelocity>5 5 5</maximumLinearVelocity>
        <maximumAngularVelocity>3 3 3</maximumAngularVelocity>
        <linearVelocityNoiseMean>0 0 0</linearVelocityNoiseMean>
        <linearVelocityNoiseStdDev>0.1105 0.1261 0.0947</linearVelocityNoiseStdDev>
        <angularVelocityNoiseMean>0 0 0</angularVelocityNoiseMean>
        <angularVelocityNoiseStdDev>0.004 0.004 0.004</angularVelocityNoiseStdDev>
        <rotorConfiguration>
          <rotor>
            <jointName>rotor_0_joint</jointName>
            <forceConstant>1.269e-05</forceConstant>
            <momentConstant>1.6754e-2</momentConstant>
            <direction>1</direction>
          </rotor>
          <rotor>
            <jointName>rotor_1_joint</jointName>
            <forceConstant>1.269e-05</forceConstant>
            <momentConstant>1.6754e-2</momentConstant>
            <direction>-1</direction>
          </rotor>
          <rotor>
            <jointName>rotor_2_joint</jointName>
            <forceConstant>1.269e-05</forceConstant>
            <momentConstant>1.6754e-2</momentConstant>
            <direction>1</direction>
          </rotor>
          <rotor>
            <jointName>rotor_3_joint</jointName>
            <forceConstant>1.269e-05</forceConstant>
            <momentConstant>1.6754e-2</momentConstant>
            <direction>-1</direction>
          </rotor>
          <rotor>
            <jointName>rotor_4_joint</jointName>
            <forceConstant>1.269e-05</forceConstant>
            <momentConstant>1.6754e-2</momentConstant>
            <direction>1</direction>
          </rotor>
          <rotor>
            <jointName>rotor_5_joint</jointName>
            <forceConstant>1.269e-05</forceConstant>
            <momentConstant>1.6754e-2</momentConstant>
            <direction>-1</direction>
          </rotor>
        </rotorConfiguration>
      </plugin>
      <plugin name='gz::sim::systems::OdometryPublisher' filename='gz-sim-odometry-publisher-system'>
        <dimensions>3</dimensions>
      </plugin>
      <static>false</static>
      <self_collide>false</self_collide>
    </model>
    <include>
      <uri>https://fuel.gazebosim.org/1.0/OpenRobotics/models/X3 UAV</uri>
      <name>UAV_3</name>
      <pose>-1.6347941789273881 -0.25306836838239688 0.25854005728556773 2.793954313140767e-16 1.5137931387971096e-05 -1.0140807920831424e-16</pose>
      <plugin name='gz::sim::systems::MulticopterMotorModel' filename='gz-sim-multicopter-motor-model-system'>
        <robotNamespace>UAV_3</robotNamespace>
        <jointName>X3/rotor_0_joint</jointName>
        <linkName>X3/rotor_0</linkName>
        <turningDirection>ccw</turningDirection>
        <timeConstantUp>0.0125</timeConstantUp>
        <timeConstantDown>0.025</timeConstantDown>
        <maxRotVelocity>800.0</maxRotVelocity>
        <motorConstant>8.54858e-06</motorConstant>
        <momentConstant>0.016</momentConstant>
        <commandSubTopic>gazebo/command/motor_speed</commandSubTopic>
        <actuator_number>0</actuator_number>
        <rotorDragCoefficient>8.06428e-05</rotorDragCoefficient>
        <rollingMomentCoefficient>1e-06</rollingMomentCoefficient>
        <motorSpeedPubTopic>motor_speed/0</motorSpeedPubTopic>
        <rotorVelocitySlowdownSim>10</rotorVelocitySlowdownSim>
        <motorType>velocity</motorType>
      </plugin>
      <plugin name='gz::sim::systems::MulticopterMotorModel' filename='gz-sim-multicopter-motor-model-system'>
        <robotNamespace>UAV_3</robotNamespace>
        <jointName>X3/rotor_1_joint</jointName>
        <linkName>X3/rotor_1</linkName>
        <turningDirection>ccw</turningDirection>
        <timeConstantUp>0.0125</timeConstantUp>
        <timeConstantDown>0.025</timeConstantDown>
        <maxRotVelocity>800.0</maxRotVelocity>
        <motorConstant>8.54858e-06</motorConstant>
        <momentConstant>0.016</momentConstant>
        <commandSubTopic>gazebo/command/motor_speed</commandSubTopic>
        <actuator_number>1</actuator_number>
        <rotorDragCoefficient>8.06428e-05</rotorDragCoefficient>
        <rollingMomentCoefficient>1e-06</rollingMomentCoefficient>
        <motorSpeedPubTopic>motor_speed/1</motorSpeedPubTopic>
        <rotorVelocitySlowdownSim>10</rotorVelocitySlowdownSim>
        <motorType>velocity</motorType>
      </plugin>
      <plugin name='gz::sim::systems::MulticopterMotorModel' filename='gz-sim-multicopter-motor-model-system'>
        <robotNamespace>UAV_3</robotNamespace>
        <jointName>X3/rotor_2_joint</jointName>
        <linkName>X3/rotor_2</linkName>
        <turningDirection>cw</turningDirection>
        <timeConstantUp>0.0125</timeConstantUp>
        <timeConstantDown>0.025</timeConstantDown>
        <maxRotVelocity>800.0</maxRotVelocity>
        <motorConstant>8.54858e-06</motorConstant>
        <momentConstant>0.016</momentConstant>
        <commandSubTopic>gazebo/command/motor_speed</commandSubTopic>
        <actuator_number>2</actuator_number>
        <rotorDragCoefficient>8.06428e-05</rotorDragCoefficient>
        <rollingMomentCoefficient>1e-06</rollingMomentCoefficient>
        <motorSpeedPubTopic>motor_speed/2</motorSpeedPubTopic>
        <rotorVelocitySlowdownSim>10</rotorVelocitySlowdownSim>
        <motorType>velocity</motorType>
      </plugin>
      <plugin name='gz::sim::systems::MulticopterMotorModel' filename='gz-sim-multicopter-motor-model-system'>
        <robotNamespace>UAV_3</robotNamespace>
        <jointName>X3/rotor_3_joint</jointName>
        <linkName>X3/rotor_3</linkName>
        <turningDirection>cw</turningDirection>
        <timeConstantUp>0.0125</timeConstantUp>
        <timeConstantDown>0.025</timeConstantDown>
        <maxRotVelocity>800.0</maxRotVelocity>
        <motorConstant>8.54858e-06</motorConstant>
        <momentConstant>0.016</momentConstant>
        <commandSubTopic>gazebo/command/motor_speed</commandSubTopic>
        <actuator_number>3</actuator_number>
        <rotorDragCoefficient>8.06428e-05</rotorDragCoefficient>
        <rollingMomentCoefficient>1e-06</rollingMomentCoefficient>
        <motorSpeedPubTopic>motor_speed/3</motorSpeedPubTopic>
        <rotorVelocitySlowdownSim>10</rotorVelocitySlowdownSim>
        <motorType>velocity</motorType>
      </plugin>
      <plugin name='gz::sim::systems::MulticopterVelocityControl' filename='gz-sim-multicopter-control-system'>
        <robotNamespace>UAV_3</robotNamespace>
        <commandSubTopic>gazebo/command/twist</commandSubTopic>
        <enableSubTopic>enable</enableSubTopic>
        <comLinkName>X3/base_link</comLinkName>
        <velocityGain>2.7 2.7 2.7</velocityGain>
        <attitudeGain>2 3 0.15</attitudeGain>
        <angularRateGain>0.4 0.52 0.18</angularRateGain>
        <maximumLinearAcceleration>2 2 2</maximumLinearAcceleration>
        <rotorConfiguration>
          <rotor>
            <jointName>X3/rotor_0_joint</jointName>
            <forceConstant>8.54858e-06</forceConstant>
            <momentConstant>0.016</momentConstant>
            <direction>1</direction>
          </rotor>
          <rotor>
            <jointName>X3/rotor_1_joint</jointName>
            <forceConstant>8.54858e-06</forceConstant>
            <momentConstant>0.016</momentConstant>
            <direction>1</direction>
          </rotor>
          <rotor>
            <jointName>X3/rotor_2_joint</jointName>
            <forceConstant>8.54858e-06</forceConstant>
            <momentConstant>0.016</momentConstant>
            <direction>-1</direction>
          </rotor>
          <rotor>
            <jointName>X3/rotor_3_joint</jointName>
            <forceConstant>8.54858e-06</forceConstant>
            <momentConstant>0.016</momentConstant>
            <direction>-1</direction>
          </rotor>
        </rotorConfiguration>
      </plugin>
      <plugin name='gz::sim::systems::OdometryPublisher'
          filename='gz-sim-odometry-publisher-system'>
       <dimensions>3</dimensions>
      </plugin>
    </include>
    <include>
      <uri>https://fuel.gazebosim.org/1.0/OpenRobotics/models/X3 UAV</uri>
      <name>UAV_4</name>
      <pose>-1.7154725476883472 2.843979831803932 0.25854005732012664 -1.2800604531939571e-17 1.5129206849873864e-05 -1.3249688695195903e-16</pose>
      <plugin name='gz::sim::systems::MulticopterMotorModel' filename='gz-sim-multicopter-motor-model-system'>
        <robotNamespace>UAV_4</robotNamespace>
        <jointName>X3/rotor_0_joint</jointName>
        <linkName>X3/rotor_0</linkName>
        <turningDirection>ccw</turningDirection>
        <timeConstantUp>0.0125</timeConstantUp>
        <timeConstantDown>0.025</timeConstantDown>
        <maxRotVelocity>800.0</maxRotVelocity>
        <motorConstant>8.54858e-06</motorConstant>
        <momentConstant>0.016</momentConstant>
        <commandSubTopic>gazebo/command/motor_speed</commandSubTopic>
        <actuator_number>0</actuator_number>
        <rotorDragCoefficient>8.06428e-05</rotorDragCoefficient>
        <rollingMomentCoefficient>1e-06</rollingMomentCoefficient>
        <motorSpeedPubTopic>motor_speed/0</motorSpeedPubTopic>
        <rotorVelocitySlowdownSim>10</rotorVelocitySlowdownSim>
        <motorType>velocity</motorType>
      </plugin>
      <plugin name='gz::sim::systems::MulticopterMotorModel' filename='gz-sim-multicopter-motor-model-system'>
        <robotNamespace>UAV_4</robotNamespace>
        <jointName>X3/rotor_1_joint</jointName>
        <linkName>X3/rotor_1</linkName>
        <turningDirection>ccw</turningDirection>
        <timeConstantUp>0.0125</timeConstantUp>
        <timeConstantDown>0.025</timeConstantDown>
        <maxRotVelocity>800.0</maxRotVelocity>
        <motorConstant>8.54858e-06</motorConstant>
        <momentConstant>0.016</momentConstant>
        <commandSubTopic>gazebo/command/motor_speed</commandSubTopic>
        <actuator_number>1</actuator_number>
        <rotorDragCoefficient>8.06428e-05</rotorDragCoefficient>
        <rollingMomentCoefficient>1e-06</rollingMomentCoefficient>
        <motorSpeedPubTopic>motor_speed/1</motorSpeedPubTopic>
        <rotorVelocitySlowdownSim>10</rotorVelocitySlowdownSim>
        <motorType>velocity</motorType>
      </plugin>
      <plugin name='gz::sim::systems::MulticopterMotorModel' filename='gz-sim-multicopter-motor-model-system'>
        <robotNamespace>UAV_4</robotNamespace>
        <jointName>X3/rotor_2_joint</jointName>
        <linkName>X3/rotor_2</linkName>
        <turningDirection>cw</turningDirection>
        <timeConstantUp>0.0125</timeConstantUp>
        <timeConstantDown>0.025</timeConstantDown>
        <maxRotVelocity>800.0</maxRotVelocity>
        <motorConstant>8.54858e-06</motorConstant>
        <momentConstant>0.016</momentConstant>
        <commandSubTopic>gazebo/command/motor_speed</commandSubTopic>
        <actuator_number>2</actuator_number>
        <rotorDragCoefficient>8.06428e-05</rotorDragCoefficient>
        <rollingMomentCoefficient>1e-06</rollingMomentCoefficient>
        <motorSpeedPubTopic>motor_speed/2</motorSpeedPubTopic>
        <rotorVelocitySlowdownSim>10</rotorVelocitySlowdownSim>
        <motorType>velocity</motorType>
      </plugin>
      <plugin name='gz::sim::systems::MulticopterMotorModel' filename='gz-sim-multicopter-motor-model-system'>
        <robotNamespace>UAV_4</robotNamespace>
        <jointName>X3/rotor_3_joint</jointName>
        <linkName>X3/rotor_3</linkName>
        <turningDirection>cw</turningDirection>
        <timeConstantUp>0.0125</timeConstantUp>
        <timeConstantDown>0.025</timeConstantDown>
        <maxRotVelocity>800.0</maxRotVelocity>
        <motorConstant>8.54858e-06</motorConstant>
        <momentConstant>0.016</momentConstant>
        <commandSubTopic>gazebo/command/motor_speed</commandSubTopic>
        <actuator_number>3</actuator_number>
        <rotorDragCoefficient>8.06428e-05</rotorDragCoefficient>
        <rollingMomentCoefficient>1e-06</rollingMomentCoefficient>
        <motorSpeedPubTopic>motor_speed/3</motorSpeedPubTopic>
        <rotorVelocitySlowdownSim>10</rotorVelocitySlowdownSim>
        <motorType>velocity</motorType>
      </plugin>
      <plugin name='gz::sim::systems::MulticopterVelocityControl' filename='gz-sim-multicopter-control-system'>
        <robotNamespace>UAV_4</robotNamespace>
        <commandSubTopic>gazebo/command/twist</commandSubTopic>
        <enableSubTopic>enable</enableSubTopic>
        <comLinkName>X3/base_link</comLinkName>
        <velocityGain>2.7 2.7 2.7</velocityGain>
        <attitudeGain>2 3 0.15</attitudeGain>
        <angularRateGain>0.4 0.52 0.18</angularRateGain>
        <maximumLinearAcceleration>2 2 2</maximumLinearAcceleration>
        <rotorConfiguration>
          <rotor>
            <jointName>X3/rotor_0_joint</jointName>
            <forceConstant>8.54858e-06</forceConstant>
            <momentConstant>0.016</momentConstant>
            <direction>1</direction>
          </rotor>
          <rotor>
            <jointName>X3/rotor_1_joint</jointName>
            <forceConstant>8.54858e-06</forceConstant>
            <momentConstant>0.016</momentConstant>
            <direction>1</direction>
          </rotor>
          <rotor>
            <jointName>X3/rotor_2_joint</jointName>
            <forceConstant>8.54858e-06</forceConstant>
            <momentConstant>0.016</momentConstant>
            <direction>-1</direction>
          </rotor>
          <rotor>
            <jointName>X3/rotor_3_joint</jointName>
            <forceConstant>8.54858e-06</forceConstant>
            <momentConstant>0.016</momentConstant>
            <direction>-1</direction>
          </rotor>
        </rotorConfiguration>
      </plugin>
      <plugin name='gz::sim::systems::OdometryPublisher'
          filename='gz-sim-odometry-publisher-system'>
       <dimensions>3</dimensions>
      </plugin>
    </include>
    <include>
      <uri>https://fuel.gazebosim.org/1.0/OpenRobotics/models/X3 UAV</uri>
      <name>UAV_5</name>
      <pose>-1.1154740869603939 2.1439798318920911 0.25854005746180464 3.1157982278563062e-14 1.5093420413159763e-05 -5.1373425563198622e-06</pose>
      <plugin name='gz::sim::systems::MulticopterMotorModel' filename='gz-sim-multicopter-motor-model-system'>
        <robotNamespace>UAV_5</robotNamespace>
        <jointName>X3/rotor_0_joint</jointName>
        <linkName>X3/rotor_0</linkName>
        <turningDirection>ccw</turningDirection>
        <timeConstantUp>0.0125</timeConstantUp>
        <timeConstantDown>0.025</timeConstantDown>
        <maxRotVelocity>800.0</maxRotVelocity>
        <motorConstant>8.54858e-06</motorConstant>
        <momentConstant>0.016</momentConstant>
        <commandSubTopic>gazebo/command/motor_speed</commandSubTopic>
        <actuator_number>0</actuator_number>
        <rotorDragCoefficient>8.06428e-05</rotorDragCoefficient>
        <rollingMomentCoefficient>1e-06</rollingMomentCoefficient>
        <motorSpeedPubTopic>motor_speed/0</motorSpeedPubTopic>
        <rotorVelocitySlowdownSim>10</rotorVelocitySlowdownSim>
        <motorType>velocity</motorType>
      </plugin>
      <plugin name='gz::sim::systems::MulticopterMotorModel' filename='gz-sim-multicopter-motor-model-system'>
        <robotNamespace>UAV_5</robotNamespace>
        <jointName>X3/rotor_1_joint</jointName>
        <linkName>X3/rotor_1</linkName>
        <turningDirection>ccw</turningDirection>
        <timeConstantUp>0.0125</timeConstantUp>
        <timeConstantDown>0.025</timeConstantDown>
        <maxRotVelocity>800.0</maxRotVelocity>
        <motorConstant>8.54858e-06</motorConstant>
        <momentConstant>0.016</momentConstant>
        <commandSubTopic>gazebo/command/motor_speed</commandSubTopic>
        <actuator_number>1</actuator_number>
        <rotorDragCoefficient>8.06428e-05</rotorDragCoefficient>
        <rollingMomentCoefficient>1e-06</rollingMomentCoefficient>
        <motorSpeedPubTopic>motor_speed/1</motorSpeedPubTopic>
        <rotorVelocitySlowdownSim>10</rotorVelocitySlowdownSim>
        <motorType>velocity</motorType>
      </plugin>
      <plugin name='gz::sim::systems::MulticopterMotorModel' filename='gz-sim-multicopter-motor-model-system'>
        <robotNamespace>UAV_5</robotNamespace>
        <jointName>X3/rotor_2_joint</jointName>
        <linkName>X3/rotor_2</linkName>
        <turningDirection>cw</turningDirection>
        <timeConstantUp>0.0125</timeConstantUp>
        <timeConstantDown>0.025</timeConstantDown>
        <maxRotVelocity>800.0</maxRotVelocity>
        <motorConstant>8.54858e-06</motorConstant>
        <momentConstant>0.016</momentConstant>
        <commandSubTopic>gazebo/command/motor_speed</commandSubTopic>
        <actuator_number>2</actuator_number>
        <rotorDragCoefficient>8.06428e-05</rotorDragCoefficient>
        <rollingMomentCoefficient>1e-06</rollingMomentCoefficient>
        <motorSpeedPubTopic>motor_speed/2</motorSpeedPubTopic>
        <rotorVelocitySlowdownSim>10</rotorVelocitySlowdownSim>
        <motorType>velocity</motorType>
      </plugin>
      <plugin name='gz::sim::systems::MulticopterMotorModel' filename='gz-sim-multicopter-motor-model-system'>
        <robotNamespace>UAV_5</robotNamespace>
        <jointName>X3/rotor_3_joint</jointName>
        <linkName>X3/rotor_3</linkName>
        <turningDirection>cw</turningDirection>
        <timeConstantUp>0.0125</timeConstantUp>
        <timeConstantDown>0.025</timeConstantDown>
        <maxRotVelocity>800.0</maxRotVelocity>
        <motorConstant>8.54858e-06</motorConstant>
        <momentConstant>0.016</momentConstant>
        <commandSubTopic>gazebo/command/motor_speed</commandSubTopic>
        <actuator_number>3</actuator_number>
        <rotorDragCoefficient>8.06428e-05</rotorDragCoefficient>
        <rollingMomentCoefficient>1e-06</rollingMomentCoefficient>
        <motorSpeedPubTopic>motor_speed/3</motorSpeedPubTopic>
        <rotorVelocitySlowdownSim>10</rotorVelocitySlowdownSim>
        <motorType>velocity</motorType>
      </plugin>
      <plugin name='gz::sim::systems::MulticopterVelocityControl' filename='gz-sim-multicopter-control-system'>
        <robotNamespace>UAV_5</robotNamespace>
        <commandSubTopic>gazebo/command/twist</commandSubTopic>
        <enableSubTopic>enable</enableSubTopic>
        <comLinkName>X3/base_link</comLinkName>
        <velocityGain>2.7 2.7 2.7</velocityGain>
        <attitudeGain>2 3 0.15</attitudeGain>
        <angularRateGain>0.4 0.52 0.18</angularRateGain>
        <maximumLinearAcceleration>2 2 2</maximumLinearAcceleration>
        <rotorConfiguration>
          <rotor>
            <jointName>X3/rotor_0_joint</jointName>
            <forceConstant>8.54858e-06</forceConstant>
            <momentConstant>0.016</momentConstant>
            <direction>1</direction>
          </rotor>
          <rotor>
            <jointName>X3/rotor_1_joint</jointName>
            <forceConstant>8.54858e-06</forceConstant>
            <momentConstant>0.016</momentConstant>
            <direction>1</direction>
          </rotor>
          <rotor>
            <jointName>X3/rotor_2_joint</jointName>
            <forceConstant>8.54858e-06</forceConstant>
            <momentConstant>0.016</momentConstant>
            <direction>-1</direction>
          </rotor>
          <rotor>
            <jointName>X3/rotor_3_joint</jointName>
            <forceConstant>8.54858e-06</forceConstant>
            <momentConstant>0.016</momentConstant>
            <direction>-1</direction>
          </rotor>
        </rotorConfiguration>
      </plugin>
      <plugin name='gz::sim::systems::OdometryPublisher'
          filename='gz-sim-odometry-publisher-system'>
       <dimensions>3</dimensions>
      </plugin>
    </include>
    <include>
      <uri>file:///home/kelvo/.gz/fuel/fuel.gazebosim.org/openrobotics/models/nathan_benderson_park/5</uri>
      <name>nb_park</name>
      <pose>-334.73693381712229 -1470.6768130818227 0 0 0 0</pose>
    </include>
    <light name='sun' type='directional'>
      <pose>0 0 10 0 0 0</pose>
      <cast_shadows>true</cast_shadows>
      <intensity>1</intensity>
      <direction>-0.5 0.10000000000000001 -0.90000000000000002</direction>
      <diffuse>0.800000012 0.800000012 0.800000012 1</diffuse>
      <specular>0.200000003 0.200000003 0.200000003 1</specular>
      <attenuation>
        <range>1000</range>
        <linear>0.0099999997764825821</linear>
        <constant>0.89999997615814209</constant>
        <quadratic>0.0010000000474974513</quadratic>
      </attenuation>
      <spot>
        <inner_angle>0</inner_angle>
        <outer_angle>0</outer_angle>
        <falloff>0</falloff>
      </spot>
    </light>
  </world>
</sdf>
